Workbook

Sheet data
A1: order_id | B1: order_date | C1: ship_date | D1: customer_id | E1: customer_name | F1: segment | G1: region | H1: state | I1: city | J1: category | K1: sub_category | L1: product_name | M1: ship_mode | N1: quantity | O1: unit_price | P1: discount | Q1: sales | R1: cost | S1: profit | T1: payment_status | U1: order_status | V1: Profit Margin | W1: Order moth | X1: Order Year | Y1: Shipping_Delay_Days | Z1: Cleaned Discount | AA1: Calculated Sales | AB1: Calculated Profit | AC1: Data Quality Flag
A2: ORD-2024-10001 | B2: 45494 | C2: 45500 | D2: CUST-4655 | E2: =PROPER(TRIM([1]raw_orders!E2)) -> Karan Malhotra | F2: =PROPER(TRIM([1]raw_orders!F2)) -> Consumer | G2: =IF('[1]Cleaned Text Field'!G2="","Unknown",'[1]Cleaned Text Field'!G2) -> North | H2: =PROPER(TRIM([1]raw_orders!H2)) -> Rajasthan | I2: =PROPER(TRIM([1]raw_orders!I2)) -> Jaipur | J2: =PROPER(TRIM([1]raw_orders!J2)) -> Office Supplies | K2: =PROPER(TRIM([1]raw_orders!K2)) -> Paper | L2: Pro Paper 122 | M2: =IF('[1]Cleaned Text Field'!M2="","Unknown",'[1]Cleaned Text Field'!M2) -> Second Class | N2: =IF('[1]Cleaned Text Field'!N2="",0,'[1]Cleaned Text Field'!N2) -> 8 | O2: 2976.45 | P2: =IF('[1]Cleaned Text Field'!P2="",0,'[1]Cleaned Text Field'!P2) -> 0.2 | Q2: 19049.28 | R2: 15841.89 | S2: 3207.39 | T2: =PROPER(TRIM([1]raw_orders!T2)) -> Paid | U2: =PROPER(TRIM([1]raw_orders!U2)) -> Completed | V2: =IF(Q2=0,0,S2/Q2) -> 0.16837329 | W2: =TEXT(B2,"mmmm") -> July | X2: =YEAR(B2) -> 2024 | Y2: =C2-B2 -> 6 | Z2: =P2 -> 0.2 | AA2: =N2*O2*(1-P2) -> 19049.28 | AB2: =Q2-R2 -> 3207.39 | AC2: =IF(OR(B2="",C2="",AA2<=0),"Invalid",IF(Y2<0,"Warning",IF(Z2>100%,"Warning","Clean"))) -> Clean
A3: ORD-2024-10002 | B3: 45535 | C3: 45540 | D3: CUST-2054 | E3: =PROPER(TRIM([1]raw_orders!E3)) -> Mira Das | F3: =PROPER(TRIM([1]raw_orders!F3)) -> Small Business | G3: =IF('[1]Cleaned Text Field'!G3="","Unknown",'[1]Cleaned Text Field'!G3) -> East | H3: =PROPER(TRIM([1]raw_orders!H3)) -> Odisha | I3: =PROPER(TRIM([1]raw_orders!I3)) -> Bhubaneswar | J3: =PROPER(TRIM([1]raw_orders!J3)) -> Furniture | K3: =PROPER(TRIM([1]raw_orders!K3)) -> Tables | L3: Pro Tables 258 | M3: =IF('[1]Cleaned Text Field'!M3="","Unknown",'[1]Cleaned Text Field'!M3) -> Same Day | N3: =IF('[1]Cleaned Text Field'!N3="",0,'[1]Cleaned Text Field'!N3) -> 3 | O3: 2437.5 | P3: =IF('[1]Cleaned Text Field'!P3="",0,'[1]Cleaned Text Field'!P3) -> 0 | Q3: 7312.5 | R3: 4904.73 | S3: 2407.77 | T3: =PROPER(TRIM([1]raw_orders!T3)) -> Paid | U3: =PROPER(TRIM([1]raw_orders!U3)) -> Completed | V3: =IF(Q3=0,0,S3/Q3) -> 0.32926769 | W3: =TEXT(B3,"mmmm") -> August | X3: =YEAR(B3) -> 2024 | Y3: =C3-B3 -> 5 | Z3: =P3 -> 0 | AA3: =N3*O3*(1-P3) -> 7312.5 | AB3: =Q3-R3 -> 2407.77 | AC3: =IF(OR(B3="",C3="",AA3<=0),"Invalid",IF(Y3<0,"Warning",IF(Z3>100%,"Warning","Clean"))) -> Clean
A4: ORD-2024-10003 | B4: 45451 | C4: 45458 | D4: CUST-6843 | E4: =PROPER(TRIM([1]raw_orders!E4)) -> Isha Nair | F4: =PROPER(TRIM([1]raw_orders!F4)) -> Consumer | G4: =IF('[1]Cleaned Text Field'!G4="","Unknown",'[1]Cleaned Text Field'!G4) -> East | H4: =PROPER(TRIM([1]raw_orders!H4)) -> Odisha | I4: =PROPER(TRIM([1]raw_orders!I4)) -> Bhubaneswar | J4: =PROPER(TRIM([1]raw_orders!J4)) -> Office Supplies | K4: =PROPER(TRIM([1]raw_orders!K4)) -> Art | L4: Elite Art 525 | M4: =IF('[1]Cleaned Text Field'!M4="","Unknown",'[1]Cleaned Text Field'!M4) -> First Class | N4: =IF('[1]Cleaned Text Field'!N4="",0,'[1]Cleaned Text Field'!N4) -> 4 | O4: 1065.43 | P4: =IF('[1]Cleaned Text Field'!P4="",0,'[1]Cleaned Text Field'!P4) -> 0.55 | Q4: 4261.72 | R4: 2465.69 | S4: 1796.03 | T4: =PROPER(TRIM([1]raw_orders!T4)) -> Paid | U4: =PROPER(TRIM([1]raw_orders!U4)) -> Completed | V4: =IF(Q4=0,0,S4/Q4) -> 0.42143313 | W4: =TEXT(B4,"mmmm") -> June | X4: =YEAR(B4) -> 2024 | Y4: =C4-B4 -> 7 | Z4: =P4 -> 0.55 | AA4: =N4*O4*(1-P4) -> 1917.774 | AB4: =Q4-R4 -> 1796.03 | AC4: =IF(OR(B4="",C4="",AA4<=0),"Invalid",IF(Y4<0,"Warning",IF(Z4>100%,"Warning","Clean"))) -> Clean
A5: ORD-2024-10004 | B5: 45624 | C5: 45625 | D5: CUST-3722 | E5: =PROPER(TRIM([1]raw_orders!E5)) -> Arjun Bose | F5: =PROPER(TRIM([1]raw_orders!F5)) -> Small Business | G5: =IF('[1]Cleaned Text Field'!G5="","Unknown",'[1]Cleaned Text Field'!G5) -> South | H5: =PROPER(TRIM([1]raw_orders!H5)) -> Telangana | I5: =PROPER(TRIM([1]raw_orders!I5)) -> Hyderabad | J5: =PROPER(TRIM([1]raw_orders!J5)) -> Furniture | K5: =PROPER(TRIM([1]raw_orders!K5)) -> Furnishings | L5: Smart Furnishings 294 | M5: =IF('[1]Cleaned Text Field'!M5="","Unknown",'[1]Cleaned Text Field'!M5) -> Standard Class | N5: =IF('[1]Cleaned Text Field'!N5="",0,'[1]Cleaned Text Field'!N5) -> 6 | O5: 1848.43 | P5: =IF('[1]Cleaned Text Field'!P5="",0,'[1]Cleaned Text Field'!P5) -> 0.25 | Q5: 8317.93 | R5: 6796.77 | S5: 1521.16 | T5: =PROPER(TRIM([1]raw_orders!T5)) -> Paid | U5: =PROPER(TRIM([1]raw_orders!U5)) -> Completed | V5: =IF(Q5=0,0,S5/Q5) -> 0.18287723 | W5: =TEXT(B5,"mmmm") -> November | X5: =YEAR(B5) -> 2024 | Y5: =C5-B5 -> 1 | Z5: =P5 -> 0.25 | AA5: =N5*O5*(1-P5) -> 8317.935 | AB5: =Q5-R5 -> 1521.16 | AC5: =IF(OR(B5="",C5="",AA5<=0),"Invalid",IF(Y5<0,"Warning",IF(Z5>100%,"Warning","Clean"))) -> Clean
A6: ORD-2025-10005 | B6: 45898 | C6: 45901 | D6: CUST-8130 | E6: =PROPER(TRIM([1]raw_orders!E6)) -> Ananya Rao | F6: =PROPER(TRIM([1]raw_orders!F6)) -> Small Business | G6: =IF('[1]Cleaned Text Field'!G6="","Unknown",'[1]Cleaned Text Field'!G6) -> West | H6: =PROPER(TRIM([1]raw_orders!H6)) -> Maharashtra | I6: =PROPER(TRIM([1]raw_orders!I6)) -> Mumbai | J6: =PROPER(TRIM([1]raw_orders!J6)) -> Furniture | K6: =PROPER(TRIM([1]raw_orders!K6)) -> Chairs | L6: Elite Chairs 543 | M6: =IF('[1]Cleaned Text Field'!M6="","Unknown",'[1]Cleaned Text Field'!M6) -> First Class | N6: =IF('[1]Cleaned Text Field'!N6="",0,'[1]Cleaned Text Field'!N6) -> 7 | O6: 2973.76 | P6: =IF('[1]Cleaned Text Field'!P6="",0,'[1]Cleaned Text Field'!P6) -> 0 | Q6: 20816.32 | R6: 17705.37 | S6: 3110.95 | T6: =PROPER(TRIM([1]raw_orders!T6)) -> Paid | U6: =PROPER(TRIM([1]raw_orders!U6)) -> Cancelled | V6: =IF(Q6=0,0,S6/Q6) -> 0.14944764 | W6: =TEXT(B6,"mmmm") -> August | X6: =YEAR(B6) -> 2025 | Y6: =C6-B6 -> 3 | Z6: =P6 -> 0 | AA6: =N6*O6*(1-P6) -> 20816.32 | AB6: =Q6-R6 -> 3110.95 | AC6: =IF(OR(B6="",C6="",AA6<=0),"Invalid",IF(Y6<0,"Warning",IF(Z6>100%,"Warning","Clean"))) -> Clean
A7: ORD-2024-10006 | B7: 45436 | C7: 45440 | D7: CUST-6056 | E7: =PROPER(TRIM([1]raw_orders!E7)) -> Vikram Iyer | F7: =PROPER(TRIM([1]raw_orders!F7)) -> Small Business | G7: =IF('[1]Cleaned Text Field'!G7="","Unknown",'[1]Cleaned Text Field'!G7) -> West | H7: =PROPER(TRIM([1]raw_orders!H7)) -> Madhya Pradesh | I7: =PROPER(TRIM([1]raw_orders!I7)) -> Indore | J7: =PROPER(TRIM([1]raw_orders!J7)) -> Technology | K7: =PROPER(TRIM([1]raw_orders!K7)) -> Accessories | L7: Pro Accessories 821 | M7: =IF('[1]Cleaned Text Field'!M7="","Unknown",'[1]Cleaned Text Field'!M7) -> Same Day | N7: =IF('[1]Cleaned Text Field'!N7="",0,'[1]Cleaned Text Field'!N7) -> 3 | O7: 1053.11 | P7: =IF('[1]Cleaned Text Field'!P7="",0,'[1]Cleaned Text Field'!P7) -> 0.2 | Q7: 2527.46 | R7: 1533.58 | S7: 993.88 | T7: =PROPER(TRIM([1]raw_orders!T7)) -> Paid | U7: =PROPER(TRIM([1]raw_orders!U7)) -> Completed | V7: =IF(Q7=0,0,S7/Q7) -> 0.39323273 | W7: =TEXT(B7,"mmmm") -> May | X7: =YEAR(B7) -> 2024 | Y7: =C7-B7 -> 4 | Z7: =P7 -> 0.2 | AA7: =N7*O7*(1-P7) -> 2527.464 | AB7: =Q7-R7 -> 993.88 | AC7: =IF(OR(B7="",C7="",AA7<=0),"Invalid",IF(Y7<0,"Warning",IF(Z7>100%,"Warning","Clean"))) -> Clean
A8: ORD-2025-10007 | B8: 45757 | C8: 45763 | D8: CUST-3656 | E8: =PROPER(TRIM([1]raw_orders!E8)) -> Neha Gupta | F8: =PROPER(TRIM([1]raw_orders!F8)) -> Consumer | G8: =IF('[1]Cleaned Text Field'!G8="","Unknown",'[1]Cleaned Text Field'!G8) -> East | H8: =PROPER(TRIM([1]raw_orders!H8)) -> Odisha | I8: =PROPER(TRIM([1]raw_orders!I8)) -> Bhubaneswar | J8: =PROPER(TRIM([1]raw_orders!J8)) -> Technology | K8: =PROPER(TRIM([1]raw_orders!K8)) -> Copiers | L8: Eco Copiers 790 | M8: =IF('[1]Cleaned Text Field'!M8="","Unknown",'[1]Cleaned Text Field'!M8) -> Standard Class | N8: =IF('[1]Cleaned Text Field'!N8="",0,'[1]Cleaned Text Field'!N8) -> 4 | O8: 1719.87 | P8: =IF('[1]Cleaned Text Field'!P8="",0,'[1]Cleaned Text Field'!P8) -> 0.15 | Q8: 5847.56 | R8: 4727.25 | S8: 1120.31 | T8: =PROPER(TRIM([1]raw_orders!T8)) -> Paid | U8: =PROPER(TRIM([1]raw_orders!U8)) -> Completed | V8: =IF(Q8=0,0,S8/Q8) -> 0.19158589 | W8: =TEXT(B8,"mmmm") -> April | X8: =YEAR(B8) -> 2025 | Y8: =C8-B8 -> 6 | Z8: =P8 -> 0.15 | AA8: =N8*O8*(1-P8) -> 5847.558 | AB8: =Q8-R8 -> 1120.31 | AC8: =IF(OR(B8="",C8="",AA8<=0),"Invalid",IF(Y8<0,"Warning",IF(Z8>100%,"Warning","Clean"))) -> Clean
A9: ORD-2025-10008 | B9: 45711 | C9: 45714 | D9: CUST-4683 | E9: =PROPER(TRIM([1]raw_orders!E9)) -> Isha Nair | F9: =PROPER(TRIM([1]raw_orders!F9)) -> Small Business | G9: =IF('[1]Cleaned Text Field'!G9="","Unknown",'[1]Cleaned Text Field'!G9) -> South | H9: =PROPER(TRIM([1]raw_orders!H9)) -> Andhra Pradesh | I9: =PROPER(TRIM([1]raw_orders!I9)) -> Vijayawada | J9: =PROPER(TRIM([1]raw_orders!J9)) -> Office Supplies | K9: =PROPER(TRIM([1]raw_orders!K9)) -> Art | L9: Eco Art 848 | M9: =IF('[1]Cleaned Text Field'!M9="","Unknown",'[1]Cleaned Text Field'!M9) -> First Class | N9: =IF('[1]Cleaned Text Field'!N9="",0,'[1]Cleaned Text Field'!N9) -> 1 | O9: 2980.71 | P9: =IF('[1]Cleaned Text Field'!P9="",0,'[1]Cleaned Text Field'!P9) -> 0 | Q9: 2980.71 | R9: 2357.22 | S9: 623.49 | T9: =PROPER(TRIM([1]raw_orders!T9)) -> Paid | U9: =PROPER(TRIM([1]raw_orders!U9)) -> Completed | V9: =IF(Q9=0,0,S9/Q9) -> 0.209175 | W9: =TEXT(B9,"mmmm") -> February | X9: =YEAR(B9) -> 2025 | Y9: =C9-B9 -> 3 | Z9: =P9 -> 0 | AA9: =N9*O9*(1-P9) -> 2980.71 | AB9: =Q9-R9 -> 623.49 | AC9: =IF(OR(B9="",C9="",AA9<=0),"Invalid",IF(Y9<0,"Warning",IF(Z9>100%,"Warning","Clean"))) -> Clean
A10: ORD-2024-10009 | B10: 45601 | C10: 45606 | D10: CUST-2598 | E10: =PROPER(TRIM([1]raw_orders!E10)) -> Aditi Sen | F10: =PROPER(TRIM([1]raw_orders!F10)) -> Corporate | G10: =IF('[1]Cleaned Text Field'!G10="","Unknown",'[1]Cleaned Text Field'!G10) -> South | H10: =PROPER(TRIM([1]raw_orders!H10)) -> Telangana | I10: =PROPER(TRIM([1]raw_orders!I10)) -> Hyderabad | J10: =PROPER(TRIM([1]raw_orders!J10)) -> Office Supplies | K10: =PROPER(TRIM([1]raw_orders!K10)) -> Labels | L10: Classic Labels 815 | M10: =IF('[1]Cleaned Text Field'!M10="","Unknown",'[1]Cleaned Text Field'!M10) -> First Class | N10: =IF('[1]Cleaned Text Field'!N10="",0,'[1]Cleaned Text Field'!N10) -> 8 | O10: 3134.2 | P10: =IF('[1]Cleaned Text Field'!P10="",0,'[1]Cleaned Text Field'!P10) -> 0 | Q10: 25073.6 | R10: 17347.23 | S10: 7726.37 | T10: =PROPER(TRIM([1]raw_orders!T10)) -> Paid | U10: =PROPER(TRIM([1]raw_orders!U10)) -> Completed | V10: =IF(Q10=0,0,S10/Q10) -> 0.30814761 | W10: =TEXT(B10,"mmmm") -> November | X10: =YEAR(B10) -> 2024 | Y10: =C10-B10 -> 5 | Z10: =P10 -> 0 | AA10: =N10*O10*(1-P10) -> 25073.6 | AB10: =Q10-R10 -> 7726.37 | AC10: =IF(OR(B10="",C10="",AA10<=0),"Invalid",IF(Y10<0,"Warning",IF(Z10>100%,"Warning","Clean"))) -> Clean
A11: ORD-2025-10010 | B11: 45847 | C11: 45912 | D11: CUST-2483 | E11: =PROPER(TRIM([1]raw_orders!E11)) -> Mira Das | F11: =PROPER(TRIM([1]raw_orders!F11)) -> Home Office | G11: =IF('[1]Cleaned Text Field'!G11="","Unknown",'[1]Cleaned Text Field'!G11) -> South | H11: =PROPER(TRIM([1]raw_orders!H11)) -> Telangana | I11: =PROPER(TRIM([1]raw_orders!I11)) -> Hyderabad | J11: =PROPER(TRIM([1]raw_orders!J11)) -> Office Supplies | K11: =PROPER(TRIM([1]raw_orders!K11)) -> Paper | L11: Pro Paper 622 | M11: =IF('[1]Cleaned Text Field'!M11="","Unknown",'[1]Cleaned Text Field'!M11) -> Second Class | N11: =IF('[1]Cleaned Text Field'!N11="",0,'[1]Cleaned Text Field'!N11) -> 9 | O11: 852.04 | P11: =IF('[1]Cleaned Text Field'!P11="",0,'[1]Cleaned Text Field'!P11) -> 0.2 | Q11: 6134.69 | R11: 3800.19 | S11: 2334.5 | T11: =PROPER(TRIM([1]raw_orders!T11)) -> Paid | U11: =PROPER(TRIM([1]raw_orders!U11)) -> Completed | V11: =IF(Q11=0,0,S11/Q11) -> 0.38054083 | W11: =TEXT(B11,"mmmm") -> July | X11: =YEAR(B11) -> 2025 | Y11: =C11-B11 -> 65 | Z11: =P11 -> 0.2 | AA11: =N11*O11*(1-P11) -> 6134.688 | AB11: =Q11-R11 -> 2334.5 | AC11: =IF(OR(B11="",C11="",AA11<=0),"Invalid",IF(Y11<0,"Warning",IF(Z11>100%,"Warning","Clean"))) -> Clean
A12: ORD-2025-10011 | B12: 45797 | C12: 45797 | D12: CUST-8092 | E12: =PROPER(TRIM([1]raw_orders!E12)) -> Ananya Rao | F12: =PROPER(TRIM([1]raw_orders!F12)) -> Corporate | G12: =IF('[1]Cleaned Text Field'!G12="","Unknown",'[1]Cleaned Text Field'!G12) -> East | H12: =PROPER(TRIM([1]raw_orders!H12)) -> West Bengal | I12: =PROPER(TRIM([1]raw_orders!I12)) -> Kolkata | J12: =PROPER(TRIM([1]raw_orders!J12)) -> Office Supplies | K12: =PROPER(TRIM([1]raw_orders!K12)) -> Labels | L12: Prime Labels 644 | M12: =IF('[1]Cleaned Text Field'!M12="","Unknown",'[1]Cleaned Text Field'!M12) -> Second Class | N12: =IF('[1]Cleaned Text Field'!N12="",0,'[1]Cleaned Text Field'!N12) -> 3 | O12: 3534.83 | P12: =IF('[1]Cleaned Text Field'!P12="",0,'[1]Cleaned Text Field'!P12) -> 0.05 | Q12: 10074.27 | R12: 6048.27 | S12: 4026 | T12: =PROPER(TRIM([1]raw_orders!T12)) -> Refunded | U12: =PROPER(TRIM([1]raw_orders!U12)) -> Returned | V12: =IF(Q12=0,0,S12/Q12) -> 0.39963193 | W12: =TEXT(B12,"mmmm") -> May | X12: =YEAR(B12) -> 2025 | Y12: =C12-B12 -> 0 | Z12: =P12 -> 0.05 | AA12: =N12*O12*(1-P12) -> 10074.265 | AB12: =Q12-R12 -> 4026 | AC12: =IF(OR(B12="",C12="",AA12<=0),"Invalid",IF(Y12<0,"Warning",IF(Z12>100%,"Warning","Clean"))) -> Clean
A13: ORD-2024-10012 | B13: 45495 | C13: 45496 | D13: CUST-6528 | E13: =PROPER(TRIM([1]raw_orders!E13)) -> Vikram Iyer | F13: =PROPER(TRIM([1]raw_orders!F13)) -> Small Business | G13: =IF('[1]Cleaned Text Field'!G13="","Unknown",'[1]Cleaned Text Field'!G13) -> East | H13: =PROPER(TRIM([1]raw_orders!H13)) -> Odisha | I13: =PROPER(TRIM([1]raw_orders!I13)) -> Bhubaneswar | J13: =PROPER(TRIM([1]raw_orders!J13)) -> Technology | K13: =PROPER(TRIM([1]raw_orders!K13)) -> Accessories | L13: Smart Accessories 603 | M13: =IF('[1]Cleaned Text Field'!M13="","Unknown",'[1]Cleaned Text Field'!M13) -> Same Day | N13: =IF('[1]Cleaned Text Field'!N13="",0,'[1]Cleaned Text Field'!N13) -> 6 | O13: 2005.95 | P13: =IF('[1]Cleaned Text Field'!P13="",0,'[1]Cleaned Text Field'!P13) -> 0.2 | Q13: 9628.56 | R13: 8038.59 | S13: 1589.97 | T13: =PROPER(TRIM([1]raw_orders!T13)) -> Paid | U13: =PROPER(TRIM([1]raw_orders!U13)) -> Completed | V13: =IF(Q13=0,0,S13/Q13) -> 0.16513061 | W13: =TEXT(B13,"mmmm") -> July | X13: =YEAR(B13) -> 2024 | Y13: =C13-B13 -> 1 | Z13: =P13 -> 0.2 | AA13: =N13*O13*(1-P13) -> 9628.56 | AB13: =Q13-R13 -> 1589.97 | AC13: =IF(OR(B13="",C13="",AA13<=0),"Invalid",IF(Y13<0,"Warning",IF(Z13>100%,"Warning","Clean"))) -> Clean
... A118: ORD-2025-10117 | B118: 45703 | C118: 45707 | D118: CUST-3632 | E118: =PROPER(TRIM([1]raw_orders!E118)) -> Ananya Rao | F118: =PROPER(TRIM([1]raw_orders!F118)) -> Small Business | G118: =IF('[1]Cleaned Text Field'!G118="","Unknown",'[1]Cleaned Text Field'!G118) -> Unknown | H118: =PROPER(TRIM([1]raw_orders!H118)) -> Madhya Pradesh | I118: =PROPER(TRIM([1]raw_orders!I118)) -> Indore | J118: =PROPER(TRIM([1]raw_orders!J118)) -> Office Supplies | K118: =PROPER(TRIM([1]raw_orders!K118)) -> Binders | L118: Basic Binders 859 | M118: =IF('[1]Cleaned Text Field'!M118="","Unknown",'[1]Cleaned Text Field'!M118) -> First Class | N118: =IF('[1]Cleaned Text Field'!N118="",0,'[1]Cleaned Text Field'!N118) -> 9 | O118: 531.99 | P118: =IF('[1]Cleaned Text Field'!P118="",0,'[1]Cleaned Text Field'!P118) -> 0.25 | Q118: 3590.93 | R118: 3061.39 | S118: 529.54 | T118: =PROPER(TRIM([1]raw_orders!T118)) -> Failed | U118: =PROPER(TRIM([1]raw_orders!U118)) -> Cancelled | V118: =IF(Q118=0,0,S118/Q118) -> 0.14746598 | W118: =TEXT(B118,"mmmm") -> February | X118: =YEAR(B118) -> 2025 | Y118: =C118-B118 -> 4 | Z118: =P118 -> 0.25 | AA118: =N118*O118*(1-P118) -> 3590.9325 | AB118: =Q118-R118 -> 529.54 | AC118: =IF(OR(B118="",C118="",AA118<=0),"Invalid",IF(Y118<0,"Warning",IF(Z118>100%,"Warning","Clean"))) -> Clean
A119: ORD-2024-10118 | B119: 45337 | C119: 45339 | D119: CUST-9608 | E119: =PROPER(TRIM([1]raw_orders!E119)) -> Mira Das | F119: =PROPER(TRIM([1]raw_orders!F119)) -> Home Office | G119: =IF('[1]Cleaned Text Field'!G119="","Unknown",'[1]Cleaned Text Field'!G119) -> South | H119: =PROPER(TRIM([1]raw_orders!H119)) -> Tamil Nadu | I119: =PROPER(TRIM([1]raw_orders!I119)) -> Chennai | J119: =PROPER(TRIM([1]raw_orders!J119)) -> Technology | K119: =PROPER(TRIM([1]raw_orders!K119)) -> Machines | L119: Elite Machines 705 | M119: =IF('[1]Cleaned Text Field'!M119="","Unknown",'[1]Cleaned Text Field'!M119) -> Standard Class | N119: =IF('[1]Cleaned Text Field'!N119="",0,'[1]Cleaned Text Field'!N119) -> 9 | O119: 3324.55 | P119: =IF('[1]Cleaned Text Field'!P119="",0,'[1]Cleaned Text Field'!P119) -> 70% | Q119: 25432.81 | R119: 20370.16 | S119: 5062.65 | T119: =PROPER(TRIM([1]raw_orders!T119)) -> Paid | U119: =PROPER(TRIM([1]raw_orders!U119)) -> Completed | V119: =IF(Q119=0,0,S119/Q119) -> 0.1990598 | W119: =TEXT(B119,"mmmm") -> February | X119: =YEAR(B119) -> 2024 | Y119: =C119-B119 -> 2 | Z119: =VALUE(SUBSTITUTE(P119,"%",""))/100 -> 0.7 | AA119: =N119*O119*(1-P119) -> 8976.285 | AB119: =Q119-R119 -> 5062.65 | AC119: =IF(OR(B119="",C119="",AA119<=0),"Invalid",IF(Y119<0,"Warning",IF(Z119>100%,"Warning","Clean"))) -> Clean
A120: ORD-2024-10119 | B120: 45453 | C120: 45461 | D120: CUST-9135 | E120: =PROPER(TRIM([1]raw_orders!E120)) -> Vikram Iyer | F120: =PROPER(TRIM([1]raw_orders!F120)) -> Home Office | G120: =IF('[1]Cleaned Text Field'!G120="","Unknown",'[1]Cleaned Text Field'!G120) -> South | H120: =PROPER(TRIM([1]raw_orders!H120)) -> Andhra Pradesh | I120: =PROPER(TRIM([1]raw_orders!I120)) -> Vijayawada | J120: =PROPER(TRIM([1]raw_orders!J120)) -> Technology | K120: =PROPER(TRIM([1]raw_orders!K120)) -> Copiers | L120: Pro Copiers 208 | M120: =IF('[1]Cleaned Text Field'!M120="","Unknown",'[1]Cleaned Text Field'!M120) -> Same Day | N120: =IF('[1]Cleaned Text Field'!N120="",0,'[1]Cleaned Text Field'!N120) -> 5 | O120: 1580.27 | P120: =IF('[1]Cleaned Text Field'!P120="",0,'[1]Cleaned Text Field'!P120) -> 0.2 | Q120: 6321.08 | R120: 4407.22 | S120: 1913.86 | T120: =PROPER(TRIM([1]raw_orders!T120)) -> Paid | U120: =PROPER(TRIM([1]raw_orders!U120)) -> Completed | V120: =IF(Q120=0,0,S120/Q120) -> 0.30277421 | W120: =TEXT(B120,"mmmm") -> June | X120: =YEAR(B120) -> 2024 | Y120: =C120-B120 -> 8 | Z120: =P120 -> 0.2 | AA120: =N120*O120*(1-P120) -> 6321.08 | AB120: =Q120-R120 -> 1913.86 | AC120: =IF(OR(B120="",C120="",AA120<=0),"Invalid",IF(Y120<0,"Warning",IF(Z120>100%,"Warning","Clean"))) -> Clean
A121: ORD-2024-10120 | B121: 45455 | C121: 45462 | D121: CUST-7861 | E121: =PROPER(TRIM([1]raw_orders!E121)) -> Aditi Sen | F121: =PROPER(TRIM([1]raw_orders!F121)) -> Small Business | G121: =IF('[1]Cleaned Text Field'!G121="","Unknown",'[1]Cleaned Text Field'!G121) -> South | H121: =PROPER(TRIM([1]raw_orders!H121)) -> Kerala | I121: =PROPER(TRIM([1]raw_orders!I121)) -> Kochi | J121: =PROPER(TRIM([1]raw_orders!J121)) -> Furniture | K121: =PROPER(TRIM([1]raw_orders!K121)) -> Chairs | L121: Elite Chairs 921 | M121: =IF('[1]Cleaned Text Field'!M121="","Unknown",'[1]Cleaned Text Field'!M121) -> Standard Class | N121: =IF('[1]Cleaned Text Field'!N121="",0,'[1]Cleaned Text Field'!N121) -> 8 | O121: 314.05 | P121: =IF('[1]Cleaned Text Field'!P121="",0,'[1]Cleaned Text Field'!P121) -> 0.25 | Q121: 1884.3 | R121: 1517.69 | S121: 366.61 | T121: =PROPER(TRIM([1]raw_orders!T121)) -> Refunded | U121: =PROPER(TRIM([1]raw_orders!U121)) -> Returned | V121: =IF(Q121=0,0,S121/Q121) -> 0.19456031 | W121: =TEXT(B121,"mmmm") -> June | X121: =YEAR(B121) -> 2024 | Y121: =C121-B121 -> 7 | Z121: =P121 -> 0.25 | AA121: =N121*O121*(1-P121) -> 1884.3 | AB121: =Q121-R121 -> 366.61 | AC121: =IF(OR(B121="",C121="",AA121<=0),"Invalid",IF(Y121<0,"Warning",IF(Z121>100%,"Warning","Clean"))) -> Clean
A122: ORD-2024-10121 | B122: 45514 | C122: 45522 | D122: CUST-6096 | E122: =PROPER(TRIM([1]raw_orders!E122)) -> Sneha Kapoor | F122: =PROPER(TRIM([1]raw_orders!F122)) -> Small Business | G122: =IF('[1]Cleaned Text Field'!G122="","Unknown",'[1]Cleaned Text Field'!G122) -> East | H122: =PROPER(TRIM([1]raw_orders!H122)) -> Bihar | I122: =PROPER(TRIM([1]raw_orders!I122)) -> Patna | J122: =PROPER(TRIM([1]raw_orders!J122)) -> Technology | K122: =PROPER(TRIM([1]raw_orders!K122)) -> Phones | L122: Prime Phones 540 | M122: =IF('[1]Cleaned Text Field'!M122="","Unknown",'[1]Cleaned Text Field'!M122) -> Standard Class | N122: =IF('[1]Cleaned Text Field'!N122="",0,'[1]Cleaned Text Field'!N122) -> 1 | O122: 1823.67 | P122: =IF('[1]Cleaned Text Field'!P122="",0,'[1]Cleaned Text Field'!P122) -> 0.2 | Q122: 1458.94 | R122: 893.2 | S122: 565.74 | T122: =PROPER(TRIM([1]raw_orders!T122)) -> Paid | U122: =PROPER(TRIM([1]raw_orders!U122)) -> Returned | V122: =IF(Q122=0,0,S122/Q122) -> 0.38777469 | W122: =TEXT(B122,"mmmm") -> August | X122: =YEAR(B122) -> 2024 | Y122: =C122-B122 -> 8 | Z122: =P122 -> 0.2 | AA122: =N122*O122*(1-P122) -> 1458.936 | AB122: =Q122-R122 -> 565.74 | AC122: =IF(OR(B122="",C122="",AA122<=0),"Invalid",IF(Y122<0,"Warning",IF(Z122>100%,"Warning","Clean"))) -> Clean
A123: ORD-2025-10122 | B123: 45891 | C123: 45895 | D123: CUST-2044 | E123: =PROPER(TRIM([1]raw_orders!E123)) -> Kabir Singh | F123: =PROPER(TRIM([1]raw_orders!F123)) -> Small Business | G123: =IF('[1]Cleaned Text Field'!G123="","Unknown",'[1]Cleaned Text Field'!G123) -> South | H123: =PROPER(TRIM([1]raw_orders!H123)) -> Andhra Pradesh | I123: =PROPER(TRIM([1]raw_orders!I123)) -> Vijayawada | J123: =PROPER(TRIM([1]raw_orders!J123)) -> Technology | K123: =PROPER(TRIM([1]raw_orders!K123)) -> Machines | L123: Max Machines 948 | M123: =IF('[1]Cleaned Text Field'!M123="","Unknown",'[1]Cleaned Text Field'!M123) -> Second Class | N123: =IF('[1]Cleaned Text Field'!N123="",0,'[1]Cleaned Text Field'!N123) -> 5 | O123: 3482.92 | P123: =IF('[1]Cleaned Text Field'!P123="",0,'[1]Cleaned Text Field'!P123) -> 0 | Q123: 17414.6 | R123: 11760.91 | S123: 5653.69 | T123: =PROPER(TRIM([1]raw_orders!T123)) -> Refunded | U123: =PROPER(TRIM([1]raw_orders!U123)) -> Cancelled | V123: =IF(Q123=0,0,S123/Q123) -> 0.3246523 | W123: =TEXT(B123,"mmmm") -> August | X123: =YEAR(B123) -> 2025 | Y123: =C123-B123 -> 4 | Z123: =P123 -> 0 | AA123: =N123*O123*(1-P123) -> 17414.6 | AB123: =Q123-R123 -> 5653.69 | AC123: =IF(OR(B123="",C123="",AA123<=0),"Invalid",IF(Y123<0,"Warning",IF(Z123>100%,"Warning","Clean"))) -> Clean
A124: ORD-2024-10123 | B124: 45626 | C124: 45394 | D124: CUST-1721 | E124: =PROPER(TRIM([1]raw_orders!E124)) -> Ananya Rao | F124: =PROPER(TRIM([1]raw_orders!F124)) -> Small Business | G124: =IF('[1]Cleaned Text Field'!G124="","Unknown",'[1]Cleaned Text Field'!G124) -> East | H124: =PROPER(TRIM([1]raw_orders!H124)) -> Assam | I124: =PROPER(TRIM([1]raw_orders!I124)) -> Guwahati | J124: =PROPER(TRIM([1]raw_orders!J124)) -> Furniture | K124: =PROPER(TRIM([1]raw_orders!K124)) -> Chairs | L124: Max Chairs 786 | M124: =IF('[1]Cleaned Text Field'!M124="","Unknown",'[1]Cleaned Text Field'!M124) -> Second Class | N124: =IF('[1]Cleaned Text Field'!N124="",0,'[1]Cleaned Text Field'!N124) -> 3 | O124: 170.35 | P124: =IF('[1]Cleaned Text Field'!P124="",0,'[1]Cleaned Text Field'!P124) -> 0 | Q124: 511.05 | R124: 367.18 | S124: 143.87 | T124: =PROPER(TRIM([1]raw_orders!T124)) -> Paid | U124: =PROPER(TRIM([1]raw_orders!U124)) -> Completed | V124: =IF(Q124=0,0,S124/Q124) -> 0.28151844 | W124: =TEXT(B124,"mmmm") -> November | X124: =YEAR(B124) -> 2024 | Y124: =C124-B124 -> -232 | Z124: =P124 -> 0 | AA124: =N124*O124*(1-P124) -> 511.05 | AB124: =Q124-R124 -> 143.87 | AC124: =IF(OR(B124="",C124="",AA124<=0),"Invalid",IF(Y124<0,"Warning",IF(Z124>100%,"Warning","Clean"))) -> Warning
A125: ORD-2024-10124 | B125: 45436 | C125: 45437 | D125: CUST-1007 | E125: =PROPER(TRIM([1]raw_orders!E125)) -> Sneha Kapoor | F125: =PROPER(TRIM([1]raw_orders!F125)) -> Small Business | G125: =IF('[1]Cleaned Text Field'!G125="","Unknown",'[1]Cleaned Text Field'!G125) -> North | H125: =PROPER(TRIM([1]raw_orders!H125)) -> Punjab | I125: =PROPER(TRIM([1]raw_orders!I125)) -> Ludhiana | J125: =PROPER(TRIM([1]raw_orders!J125)) -> Technology | K125: =PROPER(TRIM([1]raw_orders!K125)) -> Copiers | L125: Max Copiers 970 | M125: =IF('[1]Cleaned Text Field'!M125="","Unknown",'[1]Cleaned Text Field'!M125) -> Same Day | N125: =IF('[1]Cleaned Text Field'!N125="",0,'[1]Cleaned Text Field'!N125) -> 1 | O125: 634.13 | P125: =IF('[1]Cleaned Text Field'!P125="",0,'[1]Cleaned Text Field'!P125) -> 0 | Q125: 634.13 | R125: 453.35 | S125: 180.78 | T125: =PROPER(TRIM([1]raw_orders!T125)) -> Refunded | U125: =PROPER(TRIM([1]raw_orders!U125)) -> Cancelled | V125: =IF(Q125=0,0,S125/Q125) -> 0.2850835 | W125: =TEXT(B125,"mmmm") -> May | X125: =YEAR(B125) -> 2024 | Y125: =C125-B125 -> 1 | Z125: =P125 -> 0 | AA125: =N125*O125*(1-P125) -> 634.13 | AB125: =Q125-R125 -> 180.78 | AC125: =IF(OR(B125="",C125="",AA125<=0),"Invalid",IF(Y125<0,"Warning",IF(Z125>100%,"Warning","Clean"))) -> Clean
A126: ORD-2024-10125 | B126: 45494 | C126: 45497 | D126: CUST-4450 | E126: =PROPER(TRIM([1]raw_orders!E126)) -> Isha Nair | F126: =PROPER(TRIM([1]raw_orders!F126)) -> Corporate | G126: =IF('[1]Cleaned Text Field'!G126="","Unknown",'[1]Cleaned Text Field'!G126) -> South | H126: =PROPER(TRIM([1]raw_orders!H126)) -> Karnataka | I126: =PROPER(TRIM([1]raw_orders!I126)) -> Bengaluru | J126: =PROPER(TRIM([1]raw_orders!J126)) -> Technology | K126: =PROPER(TRIM([1]raw_orders!K126)) -> Copiers | L126: Pro Copiers 769 | M126: =IF('[1]Cleaned Text Field'!M126="","Unknown",'[1]Cleaned Text Field'!M126) -> Standard Class | N126: =IF('[1]Cleaned Text Field'!N126="",0,'[1]Cleaned Text Field'!N126) -> 9 | O126: 465.06 | P126: =IF('[1]Cleaned Text Field'!P126="",0,'[1]Cleaned Text Field'!P126) -> -0.15 | Q126: 4185.54 | R126: 3443.74 | S126: 741.8 | T126: =PROPER(TRIM([1]raw_orders!T126)) -> Paid | U126: =PROPER(TRIM([1]raw_orders!U126)) -> Completed | V126: =IF(Q126=0,0,S126/Q126) -> 0.17722922 | W126: =TEXT(B126,"mmmm") -> July | X126: =YEAR(B126) -> 2024 | Y126: =C126-B126 -> 3 | Z126: =P126 -> -0.15 | AA126: =N126*O126*(1-P126) -> 4813.371 | AB126: =Q126-R126 -> 741.8 | AC126: =IF(OR(B126="",C126="",AA126<=0),"Invalid",IF(Y126<0,"Warning",IF(Z126>100%,"Warning","Clean"))) -> Clean
A127: ORD-2025-10126 | B127: 45855 | C127: 45856 | D127: CUST-7924 | E127: =PROPER(TRIM([1]raw_orders!E127)) -> Neha Gupta | F127: =PROPER(TRIM([1]raw_orders!F127)) -> Small Business | G127: =IF('[1]Cleaned Text Field'!G127="","Unknown",'[1]Cleaned Text Field'!G127) -> West | H127: =PROPER(TRIM([1]raw_orders!H127)) -> Rajasthan | I127: =PROPER(TRIM([1]raw_orders!I127)) -> Udaipur | J127: =PROPER(TRIM([1]raw_orders!J127)) -> Furniture | K127: =PROPER(TRIM([1]raw_orders!K127)) -> Tables | L127: Basic Tables 753 | M127: =IF('[1]Cleaned Text Field'!M127="","Unknown",'[1]Cleaned Text Field'!M127) -> Same Day | N127: =IF('[1]Cleaned Text Field'!N127="",0,'[1]Cleaned Text Field'!N127) -> 6 | O127: 3235.27 | P127: =IF('[1]Cleaned Text Field'!P127="",0,'[1]Cleaned Text Field'!P127) -> 0.25 | Q127: 14558.72 | R127: 9591.48 | S127: 4967.24 | T127: =PROPER(TRIM([1]raw_orders!T127)) -> Refunded | U127: =PROPER(TRIM([1]raw_orders!U127)) -> Returned | V127: =IF(Q127=0,0,S127/Q127) -> 0.34118659 | W127: =TEXT(B127,"mmmm") -> July | X127: =YEAR(B127) -> 2025 | Y127: =C127-B127 -> 1 | Z127: =P127 -> 0.25 | AA127: =N127*O127*(1-P127) -> 14558.715 | AB127: =Q127-R127 -> 4967.24 | AC127: =IF(OR(B127="",C127="",AA127<=0),"Invalid",IF(Y127<0,"Warning",IF(Z127>100%,"Warning","Clean"))) -> Clean
A128: ORD-2025-10127 | B128: 45924 | C128: 45926 | D128: CUST-1715 | E128: =PROPER(TRIM([1]raw_orders!E128)) -> Priya Menon | F128: =PROPER(TRIM([1]raw_orders!F128)) -> Corporate | G128: =IF('[1]Cleaned Text Field'!G128="","Unknown",'[1]Cleaned Text Field'!G128) -> North | H128: =PROPER(TRIM([1]raw_orders!H128)) -> Delhi | I128: =PROPER(TRIM([1]raw_orders!I128)) -> New Delhi | J128: =PROPER(TRIM([1]raw_orders!J128)) -> Technology | K128: =PROPER(TRIM([1]raw_orders!K128)) -> Copiers | L128: Prime Copiers 651 | M128: =IF('[1]Cleaned Text Field'!M128="","Unknown",'[1]Cleaned Text Field'!M128) -> Standard Class | N128: =IF('[1]Cleaned Text Field'!N128="",0,'[1]Cleaned Text Field'!N128) -> 3 | O128: 1593.86 | P128: =IF('[1]Cleaned Text Field'!P128="",0,'[1]Cleaned Text Field'!P128) -> 0.1 | Q128: 4303.42 | R128: 2568.57 | S128: 1734.85 | T128: =PROPER(TRIM([1]raw_orders!T128)) -> Paid | U128: =PROPER(TRIM([1]raw_orders!U128)) -> Completed | V128: =IF(Q128=0,0,S128/Q128) -> 0.40313286 | W128: =TEXT(B128,"mmmm") -> September | X128: =YEAR(B128) -> 2025 | Y128: =C128-B128 -> 2 | Z128: =P128 -> 0.1 | AA128: =N128*O128*(1-P128) -> 4303.422 | AB128: =Q128-R128 -> 1734.85 | AC128: =IF(OR(B128="",C128="",AA128<=0),"Invalid",IF(Y128<0,"Warning",IF(Z128>100%,"Warning","Clean"))) -> Clean
A129: ORD-2025-10128 | B129: 45687 | C129: 45683 | D129: CUST-6802 | E129: =PROPER(TRIM([1]raw_orders!E129)) -> Priya Menon | F129: =PROPER(TRIM([1]raw_orders!F129)) -> Corporate | G129: =IF('[1]Cleaned Text Field'!G129="","Unknown",'[1]Cleaned Text Field'!G129) -> West | H129: =PROPER(TRIM([1]raw_orders!H129)) -> Madhya Pradesh | I129: =PROPER(TRIM([1]raw_orders!I129)) -> Indore | J129: =PROPER(TRIM([1]raw_orders!J129)) -> Office Supplies | K129: =PROPER(TRIM([1]raw_orders!K129)) -> Storage | L129: Basic Storage 321 | M129: =IF('[1]Cleaned Text Field'!M129="","Unknown",'[1]Cleaned Text Field'!M129) -> Second Class | N129: =IF('[1]Cleaned Text Field'!N129="",0,'[1]Cleaned Text Field'!N129) -> 2 | O129: 3039.3 | P129: =IF('[1]Cleaned Text Field'!P129="",0,'[1]Cleaned Text Field'!P129) -> 0.05 | Q129: 5774.67 | R129: 3518.36 | S129: 2256.31 | T129: =PROPER(TRIM([1]raw_orders!T129)) -> Paid | U129: =PROPER(TRIM([1]raw_orders!U129)) -> Completed | V129: =IF(Q129=0,0,S129/Q129) -> 0.39072536 | W129: =TEXT(B129,"mmmm") -> January | X129: =YEAR(B129) -> 2025 | Y129: =C129-B129 -> -4 | Z129: =P129 -> 0.05 | AA129: =N129*O129*(1-P129) -> 5774.67 | AB129: =Q129-R129 -> 2256.31 | AC129: =IF(OR(B129="",C129="",AA129<=0),"Invalid",IF(Y129<0,"Warning",IF(Z129>100%,"Warning","Clean"))) -> Warning
A130: ORD-2024-10129 | B130: 45639 | C130: 45642 | D130: CUST-9328 | E130: =PROPER(TRIM([1]raw_orders!E130)) -> Neha Gupta | F130: =PROPER(TRIM([1]raw_orders!F130)) -> Small Business | G130: =IF('[1]Cleaned Text Field'!G130="","Unknown",'[1]Cleaned Text Field'!G130) -> East | H130: =PROPER(TRIM([1]raw_orders!H130)) -> Odisha | I130: =PROPER(TRIM([1]raw_orders!I130)) -> Bhubaneswar | J130: =PROPER(TRIM([1]raw_orders!J130)) -> Furniture | K130: =PROPER(TRIM([1]raw_orders!K130)) -> Furnishings | L130: Prime Furnishings 710 | M130: =IF('[1]Cleaned Text Field'!M130="","Unknown",'[1]Cleaned Text Field'!M130) -> Standard Class | N130: =IF('[1]Cleaned Text Field'!N130="",0,'[1]Cleaned Text Field'!N130) -> 5 | O130: 923.45 | P130: =IF('[1]Cleaned Text Field'!P130="",0,'[1]Cleaned Text Field'!P130) -> 0.05 | Q130: 4386.39 | R130: 3366.88 | S130: 1019.51 | T130: =PROPER(TRIM([1]raw_orders!T130)) -> Paid | U130: =PROPER(TRIM([1]raw_orders!U130)) -> Returned | V130: =IF(Q130=0,0,S130/Q130) -> 0.23242575 | W130: =TEXT(B130,"mmmm") -> December | X130: =YEAR(B130) -> 2024 | Y130: =C130-B130 -> 3 | Z130: =P130 -> 0.05 | AA130: =N130*O130*(1-P130) -> 4386.3875 | AB130: =Q130-R130 -> 1019.51 | AC130: =IF(OR(B130="",C130="",AA130<=0),"Invalid",IF(Y130<0,"Warning",IF(Z130>100%,"Warning","Clean"))) -> Clean
A131: ORD-2024-10130 | B131: 45492 | C131: 45498 | D131: CUST-2588 | E131: =PROPER(TRIM([1]raw_orders!E131)) -> Isha Nair | F131: =PROPER(TRIM([1]raw_orders!F131)) -> Small Business | G131: =IF('[1]Cleaned Text Field'!G131="","Unknown",'[1]Cleaned Text Field'!G131) -> West | H131: =PROPER(TRIM([1]raw_orders!H131)) -> Goa | I131: =PROPER(TRIM([1]raw_orders!I131)) -> Panaji | J131: =PROPER(TRIM([1]raw_orders!J131)) -> Office Supplies | K131: =PROPER(TRIM([1]raw_orders!K131)) -> Binders | L131: Elite Binders 723 | M131: =IF('[1]Cleaned Text Field'!M131="","Unknown",'[1]Cleaned Text Field'!M131) -> Standard Class | N131: =IF('[1]Cleaned Text Field'!N131="",0,'[1]Cleaned Text Field'!N131) -> 7 | O131: 2741.29 | P131: =IF('[1]Cleaned Text Field'!P131="",0,'[1]Cleaned Text Field'!P131) -> 0.05 | Q131: 18229.58 | R131: 15139.15 | S131: 3090.43 | T131: =PROPER(TRIM([1]raw_orders!T131)) -> Paid | U131: =PROPER(TRIM([1]raw_orders!U131)) -> Completed | V131: =IF(Q131=0,0,S131/Q131) -> 0.16952832 | W131: =TEXT(B131,"mmmm") -> July | X131: =YEAR(B131) -> 2024 | Y131: =C131-B131 -> 6 | Z131: =P131 -> 0.05 | AA131: =N131*O131*(1-P131) -> 18229.578 | AB131: =Q131-R131 -> 3090.43 | AC131: =IF(OR(B131="",C131="",AA131<=0),"Invalid",IF(Y131<0,"Warning",IF(Z131>100%,"Warning","Clean"))) -> Clean
... A220: ORD-2025-10219 | B220: 45714 | C220: 45715 | D220: CUST-8270 | E220: =PROPER(TRIM([1]raw_orders!E220)) -> Priya Menon | F220: =PROPER(TRIM([1]raw_orders!F220)) -> Corporate | G220: =IF('[1]Cleaned Text Field'!G220="","Unknown",'[1]Cleaned Text Field'!G220) -> West | H220: =PROPER(TRIM([1]raw_orders!H220)) -> Gujarat | I220: =PROPER(TRIM([1]raw_orders!I220)) -> Ahmedabad | J220: =PROPER(TRIM([1]raw_orders!J220)) -> Furniture | K220: =PROPER(TRIM([1]raw_orders!K220)) -> Bookcases | L220: Classic Bookcases 139 | M220: =IF('[1]Cleaned Text Field'!M220="","Unknown",'[1]Cleaned Text Field'!M220) -> Standard Class | N220: =IF('[1]Cleaned Text Field'!N220="",0,'[1]Cleaned Text Field'!N220) -> 5 | O220: 258.28 | P220: =IF('[1]Cleaned Text Field'!P220="",0,'[1]Cleaned Text Field'!P220) -> 0 | Q220: 1291.4 | R220: 756.93 | S220: 534.47 | T220: =PROPER(TRIM([1]raw_orders!T220)) -> Paid | U220: =PROPER(TRIM([1]raw_orders!U220)) -> Completed | V220: =IF(Q220=0,0,S220/Q220) -> 0.41386867 | W220: =TEXT(B220,"mmmm") -> February | X220: =YEAR(B220) -> 2025 | Y220: =C220-B220 -> 1 | Z220: =P220 -> 0 | AA220: =N220*O220*(1-P220) -> 1291.4 | AB220: =Q220-R220 -> 534.47 | AC220: =IF(OR(B220="",C220="",AA220<=0),"Invalid",IF(Y220<0,"Warning",IF(Z220>100%,"Warning","Clean"))) -> Clean
A221: ORD-2024-10220 | B221: 45461 | C221: 45462 | D221: CUST-1472 | E221: =PROPER(TRIM([1]raw_orders!E221)) -> Rahul Verma | F221: =PROPER(TRIM([1]raw_orders!F221)) -> Consumer | G221: =IF('[1]Cleaned Text Field'!G221="","Unknown",'[1]Cleaned Text Field'!G221) -> East | H221: =PROPER(TRIM([1]raw_orders!H221)) -> Bihar | I221: =PROPER(TRIM([1]raw_orders!I221)) -> Patna | J221: =PROPER(TRIM([1]raw_orders!J221)) -> Technology | K221: =PROPER(TRIM([1]raw_orders!K221)) -> Machines | L221: Elite Machines 290 | M221: =IF('[1]Cleaned Text Field'!M221="","Unknown",'[1]Cleaned Text Field'!M221) -> First Class | N221: =IF('[1]Cleaned Text Field'!N221="",0,'[1]Cleaned Text Field'!N221) -> 2 | O221: 121.49 | P221: =IF('[1]Cleaned Text Field'!P221="",0,'[1]Cleaned Text Field'!P221) -> 85% | Q221: 242.98 | R221: 161.42 | S221: 81.56 | T221: =PROPER(TRIM([1]raw_orders!T221)) -> Paid | U221: =PROPER(TRIM([1]raw_orders!U221)) -> Completed | V221: =IF(Q221=0,0,S221/Q221) -> 0.33566549 | W221: =TEXT(B221,"mmmm") -> June | X221: =YEAR(B221) -> 2024 | Y221: =C221-B221 -> 1 | Z221: =VALUE(SUBSTITUTE(P221,"%",""))/100 -> 0.85 | AA221: =N221*O221*(1-P221) -> 36.447 | AB221: =Q221-R221 -> 81.56 | AC221: =IF(OR(B221="",C221="",AA221<=0),"Invalid",IF(Y221<0,"Warning",IF(Z221>100%,"Warning","Clean"))) -> Clean
A222: ORD-2024-10221 | B222: 45538 | C222: 45538 | D222: CUST-1031 | E222: =PROPER(TRIM([1]raw_orders!E222)) -> Sneha Kapoor | F222: =PROPER(TRIM([1]raw_orders!F222)) -> Consumer | G222: =IF('[1]Cleaned Text Field'!G222="","Unknown",'[1]Cleaned Text Field'!G222) -> South | H222: =PROPER(TRIM([1]raw_orders!H222)) -> Kerala | I222: =PROPER(TRIM([1]raw_orders!I222)) -> Kochi | J222: =PROPER(TRIM([1]raw_orders!J222)) -> Office Supplies | K222: =PROPER(TRIM([1]raw_orders!K222)) -> Storage | L222: Elite Storage 925 | M222: =IF('[1]Cleaned Text Field'!M222="","Unknown",'[1]Cleaned Text Field'!M222) -> First Class | N222: =IF('[1]Cleaned Text Field'!N222="",0,'[1]Cleaned Text Field'!N222) -> 4 | O222: 2810.17 | P222: =IF('[1]Cleaned Text Field'!P222="",0,'[1]Cleaned Text Field'!P222) -> 0.15 | Q222: 9554.58 | R222: 6068.47 | S222: 3486.11 | T222: =PROPER(TRIM([1]raw_orders!T222)) -> Refunded | U222: =PROPER(TRIM([1]raw_orders!U222)) -> Cancelled | V222: =IF(Q222=0,0,S222/Q222) -> 0.36486272 | W222: =TEXT(B222,"mmmm") -> September | X222: =YEAR(B222) -> 2024 | Y222: =C222-B222 -> 0 | Z222: =P222 -> 0.15 | AA222: =N222*O222*(1-P222) -> 9554.578 | AB222: =Q222-R222 -> 3486.11 | AC222: =IF(OR(B222="",C222="",AA222<=0),"Invalid",IF(Y222<0,"Warning",IF(Z222>100%,"Warning","Clean"))) -> Clean
A223: ORD-2025-10222 | B223: 45992 | C223: 45672 | D223: CUST-2495 | E223: =PROPER(TRIM([1]raw_orders!E223)) -> Mira Das | F223: =PROPER(TRIM([1]raw_orders!F223)) -> Corporate | G223: =IF('[1]Cleaned Text Field'!G223="","Unknown",'[1]Cleaned Text Field'!G223) -> South | H223: =PROPER(TRIM([1]raw_orders!H223)) -> Karnataka | I223: =PROPER(TRIM([1]raw_orders!I223)) -> Bengaluru | J223: =PROPER(TRIM([1]raw_orders!J223)) -> Furniture | K223: =PROPER(TRIM([1]raw_orders!K223)) -> Chairs | L223: Classic Chairs 231 | M223: =IF('[1]Cleaned Text Field'!M223="","Unknown",'[1]Cleaned Text Field'!M223) -> Same Day | N223: =IF('[1]Cleaned Text Field'!N223="",0,'[1]Cleaned Text Field'!N223) -> 4 | O223: 1531.53 | P223: =IF('[1]Cleaned Text Field'!P223="",0,'[1]Cleaned Text Field'!P223) -> 0.2 | Q223: 4900.9 | R223: 3552.69 | S223: 1348.21 | T223: =PROPER(TRIM([1]raw_orders!T223)) -> Paid | U223: =PROPER(TRIM([1]raw_orders!U223)) -> Completed | V223: =IF(Q223=0,0,S223/Q223) -> 0.27509437 | W223: =TEXT(B223,"mmmm") -> December | X223: =YEAR(B223) -> 2025 | Y223: =C223-B223 -> -320 | Z223: =P223 -> 0.2 | AA223: =N223*O223*(1-P223) -> 4900.896 | AB223: =Q223-R223 -> 1348.21 | AC223: =IF(OR(B223="",C223="",AA223<=0),"Invalid",IF(Y223<0,"Warning",IF(Z223>100%,"Warning","Clean"))) -> Warning
A224: ORD-2025-10223 | B224: 45776 | C224: 45779 | D224: CUST-4583 | E224: =PROPER(TRIM([1]raw_orders!E224)) -> Vikram Iyer | F224: =PROPER(TRIM([1]raw_orders!F224)) -> Small Business | G224: =IF('[1]Cleaned Text Field'!G224="","Unknown",'[1]Cleaned Text Field'!G224) -> West | H224: =PROPER(TRIM([1]raw_orders!H224)) -> Goa | I224: =PROPER(TRIM([1]raw_orders!I224)) -> Panaji | J224: =PROPER(TRIM([1]raw_orders!J224)) -> Office Supplies | K224: =PROPER(TRIM([1]raw_orders!K224)) -> Storage | L224: Prime Storage 818 | M224: =IF('[1]Cleaned Text Field'!M224="","Unknown",'[1]Cleaned Text Field'!M224) -> First Class | N224: =IF('[1]Cleaned Text Field'!N224="",0,'[1]Cleaned Text Field'!N224) -> 6 | O224: 4308.09 | P224: =IF('[1]Cleaned Text Field'!P224="",0,'[1]Cleaned Text Field'!P224) -> 0 | Q224: 25848.54 | R224: 17729.09 | S224: 8119.45 | T224: =PROPER(TRIM([1]raw_orders!T224)) -> Paid | U224: =PROPER(TRIM([1]raw_orders!U224)) -> Completed | V224: =IF(Q224=0,0,S224/Q224) -> 0.31411639 | W224: =TEXT(B224,"mmmm") -> April | X224: =YEAR(B224) -> 2025 | Y224: =C224-B224 -> 3 | Z224: =P224 -> 0 | AA224: =N224*O224*(1-P224) -> 25848.54 | AB224: =Q224-R224 -> 8119.45 | AC224: =IF(OR(B224="",C224="",AA224<=0),"Invalid",IF(Y224<0,"Warning",IF(Z224>100%,"Warning","Clean"))) -> Clean
A225: ORD-2025-10224 | B225: 45707 | C225: 45714 | D225: CUST-5319 | E225: =PROPER(TRIM([1]raw_orders!E225)) -> Mira Das | F225: =PROPER(TRIM([1]raw_orders!F225)) -> Corporate | G225: =IF('[1]Cleaned Text Field'!G225="","Unknown",'[1]Cleaned Text Field'!G225) -> West | H225: =PROPER(TRIM([1]raw_orders!H225)) -> Maharashtra | I225: =PROPER(TRIM([1]raw_orders!I225)) -> Mumbai | J225: =PROPER(TRIM([1]raw_orders!J225)) -> Furniture | K225: =PROPER(TRIM([1]raw_orders!K225)) -> Furnishings | L225: Elite Furnishings 449 | M225: =IF('[1]Cleaned Text Field'!M225="","Unknown",'[1]Cleaned Text Field'!M225) -> First Class | N225: =IF('[1]Cleaned Text Field'!N225="",0,'[1]Cleaned Text Field'!N225) -> 3 | O225: 490.3 | P225: =IF('[1]Cleaned Text Field'!P225="",0,'[1]Cleaned Text Field'!P225) -> 0.2 | Q225: 1176.72 | R225: 654.33 | S225: 522.39 | T225: =PROPER(TRIM([1]raw_orders!T225)) -> Pending | U225: =PROPER(TRIM([1]raw_orders!U225)) -> Returned | V225: =IF(Q225=0,0,S225/Q225) -> 0.44393739 | W225: =TEXT(B225,"mmmm") -> February | X225: =YEAR(B225) -> 2025 | Y225: =C225-B225 -> 7 | Z225: =P225 -> 0.2 | AA225: =N225*O225*(1-P225) -> 1176.72 | AB225: =Q225-R225 -> 522.39 | AC225: =IF(OR(B225="",C225="",AA225<=0),"Invalid",IF(Y225<0,"Warning",IF(Z225>100%,"Warning","Clean"))) -> Clean
A226: ORD-2025-10225 | B226: 45932 | C226: 45938 | D226: CUST-9871 | E226: =PROPER(TRIM([1]raw_orders!E226)) -> Isha Nair | F226: =PROPER(TRIM([1]raw_orders!F226)) -> Small Business | G226: =IF('[1]Cleaned Text Field'!G226="","Unknown",'[1]Cleaned Text Field'!G226) -> North | H226: =PROPER(TRIM([1]raw_orders!H226)) -> Punjab | I226: =PROPER(TRIM([1]raw_orders!I226)) -> Ludhiana | J226: =PROPER(TRIM([1]raw_orders!J226)) -> Furniture | K226: =PROPER(TRIM([1]raw_orders!K226)) -> Furnishings | L226: Classic Furnishings 109 | M226: =IF('[1]Cleaned Text Field'!M226="","Unknown",'[1]Cleaned Text Field'!M226) -> Standard Class | N226: =IF('[1]Cleaned Text Field'!N226="",0,'[1]Cleaned Text Field'!N226) -> 4 | O226: 3944.64 | P226: =IF('[1]Cleaned Text Field'!P226="",0,'[1]Cleaned Text Field'!P226) -> 0.25 | Q226: 11833.92 | R226: 6682.92 | S226: 5151 | T226: =PROPER(TRIM([1]raw_orders!T226)) -> Paid | U226: =PROPER(TRIM([1]raw_orders!U226)) -> Cancelled | V226: =IF(Q226=0,0,S226/Q226) -> 0.43527419 | W226: =TEXT(B226,"mmmm") -> October | X226: =YEAR(B226) -> 2025 | Y226: =C226-B226 -> 6 | Z226: =P226 -> 0.25 | AA226: =N226*O226*(1-P226) -> 11833.92 | AB226: =Q226-R226 -> 5151 | AC226: =IF(OR(B226="",C226="",AA226<=0),"Invalid",IF(Y226<0,"Warning",IF(Z226>100%,"Warning","Clean"))) -> Clean
A227: ORD-2024-10226 | B227: 45537 | C227: 45545 | D227: CUST-1266 | E227: =PROPER(TRIM([1]raw_orders!E227)) -> Mira Das | F227: =PROPER(TRIM([1]raw_orders!F227)) -> Corporate | G227: =IF('[1]Cleaned Text Field'!G227="","Unknown",'[1]Cleaned Text Field'!G227) -> West | H227: =PROPER(TRIM([1]raw_orders!H227)) -> Goa | I227: =PROPER(TRIM([1]raw_orders!I227)) -> Panaji | J227: =PROPER(TRIM([1]raw_orders!J227)) -> Technology | K227: =PROPER(TRIM([1]raw_orders!K227)) -> Phones | L227: Classic Phones 548 | M227: =IF('[1]Cleaned Text Field'!M227="","Unknown",'[1]Cleaned Text Field'!M227) -> Standard Class | N227: =IF('[1]Cleaned Text Field'!N227="",0,'[1]Cleaned Text Field'!N227) -> 6 | O227: 1032.47 | P227: =IF('[1]Cleaned Text Field'!P227="",0,'[1]Cleaned Text Field'!P227) -> 0.15 | Q227: 5265.6 | R227: 4293.11 | S227: 787.57 | T227: =PROPER(TRIM([1]raw_orders!T227)) -> Paid | U227: =PROPER(TRIM([1]raw_orders!U227)) -> Completed | V227: =IF(Q227=0,0,S227/Q227) -> 0.1495689 | W227: =TEXT(B227,"mmmm") -> September | X227: =YEAR(B227) -> 2024 | Y227: =C227-B227 -> 8 | Z227: =P227 -> 0.15 | AA227: =N227*O227*(1-P227) -> 5265.597 | AB227: =Q227-R227 -> 972.49 | AC227: =IF(OR(B227="",C227="",AA227<=0),"Invalid",IF(Y227<0,"Warning",IF(Z227>100%,"Warning","Clean"))) -> Clean
A228: ORD-2025-10227 | B228: 45934 | C228: 45762 | D228: CUST-2545 | E228: =PROPER(TRIM([1]raw_orders!E228)) -> Diya Patel | F228: =PROPER(TRIM([1]raw_orders!F228)) -> Home Office | G228: =IF('[1]Cleaned Text Field'!G228="","Unknown",'[1]Cleaned Text Field'!G228) -> Unknown | H228: =PROPER(TRIM([1]raw_orders!H228)) -> Kerala | I228: =PROPER(TRIM([1]raw_orders!I228)) -> Kochi | J228: =PROPER(TRIM([1]raw_orders!J228)) -> Technology | K228: =PROPER(TRIM([1]raw_orders!K228)) -> Copiers | L228: Max Copiers 363 | M228: =IF('[1]Cleaned Text Field'!M228="","Unknown",'[1]Cleaned Text Field'!M228) -> Same Day | N228: =IF('[1]Cleaned Text Field'!N228="",0,'[1]Cleaned Text Field'!N228) -> 1 | O228: 2208.27 | P228: =IF('[1]Cleaned Text Field'!P228="",0,'[1]Cleaned Text Field'!P228) -> 0.1 | Q228: 1987.44 | R228: 1110.23 | S228: 877.21 | T228: =PROPER(TRIM([1]raw_orders!T228)) -> Paid | U228: =PROPER(TRIM([1]raw_orders!U228)) -> Completed | V228: =IF(Q228=0,0,S228/Q228) -> 0.44137685 | W228: =TEXT(B228,"mmmm") -> October | X228: =YEAR(B228) -> 2025 | Y228: =C228-B228 -> -172 | Z228: =P228 -> 0.1 | AA228: =N228*O228*(1-P228) -> 1987.443 | AB228: =Q228-R228 -> 877.21 | AC228: =IF(OR(B228="",C228="",AA228<=0),"Invalid",IF(Y228<0,"Warning",IF(Z228>100%,"Warning","Clean"))) -> Warning
A229: ORD-2024-10228 | B229: 45478 | C229: 45485 | D229: CUST-2819 | E229: =PROPER(TRIM([1]raw_orders!E229)) -> Ananya Rao | F229: =PROPER(TRIM([1]raw_orders!F229)) -> Small Business | G229: =IF('[1]Cleaned Text Field'!G229="","Unknown",'[1]Cleaned Text Field'!G229) -> West | H229: =PROPER(TRIM([1]raw_orders!H229)) -> Goa | I229: =PROPER(TRIM([1]raw_orders!I229)) -> Panaji | J229: =PROPER(TRIM([1]raw_orders!J229)) -> Office Supplies | K229: =PROPER(TRIM([1]raw_orders!K229)) -> Binders | L229: Prime Binders 507 | M229: =IF('[1]Cleaned Text Field'!M229="","Unknown",'[1]Cleaned Text Field'!M229) -> First Class | N229: =IF('[1]Cleaned Text Field'!N229="",0,'[1]Cleaned Text Field'!N229) -> 3 | O229: 577.75 | P229: =IF('[1]Cleaned Text Field'!P229="",0,'[1]Cleaned Text Field'!P229) -> 0.15 | Q229: 1473.26 | R229: 899.86 | S229: 573.4 | T229: =PROPER(TRIM([1]raw_orders!T229)) -> Paid | U229: =PROPER(TRIM([1]raw_orders!U229)) -> Completed | V229: =IF(Q229=0,0,S229/Q229) -> 0.38920489 | W229: =TEXT(B229,"mmmm") -> July | X229: =YEAR(B229) -> 2024 | Y229: =C229-B229 -> 7 | Z229: =P229 -> 0.15 | AA229: =N229*O229*(1-P229) -> 1473.2625 | AB229: =Q229-R229 -> 573.4 | AC229: =IF(OR(B229="",C229="",AA229<=0),"Invalid",IF(Y229<0,"Warning",IF(Z229>100%,"Warning","Clean"))) -> Clean
A230: ORD-2024-10229 | B230: 45406 | C230: 45410 | D230: CUST-1076 | E230: =PROPER(TRIM([1]raw_orders!E230)) -> Karan Malhotra | F230: =PROPER(TRIM([1]raw_orders!F230)) -> Small Business | G230: =IF('[1]Cleaned Text Field'!G230="","Unknown",'[1]Cleaned Text Field'!G230) -> South | H230: =PROPER(TRIM([1]raw_orders!H230)) -> Telangana | I230: =PROPER(TRIM([1]raw_orders!I230)) -> Hyderabad | J230: =PROPER(TRIM([1]raw_orders!J230)) -> Office Supplies | K230: =PROPER(TRIM([1]raw_orders!K230)) -> Labels | L230: Smart Labels 914 | M230: =IF('[1]Cleaned Text Field'!M230="","Unknown",'[1]Cleaned Text Field'!M230) -> Second Class | N230: =IF('[1]Cleaned Text Field'!N230="",0,'[1]Cleaned Text Field'!N230) -> 1 | O230: 3194.37 | P230: =IF('[1]Cleaned Text Field'!P230="",0,'[1]Cleaned Text Field'!P230) -> 0.15 | Q230: 2715.21 | R230: 1551.55 | S230: 1163.66 | T230: =PROPER(TRIM([1]raw_orders!T230)) -> Paid | U230: =PROPER(TRIM([1]raw_orders!U230)) -> Completed | V230: =IF(Q230=0,0,S230/Q230) -> 0.4285709 | W230: =TEXT(B230,"mmmm") -> April | X230: =YEAR(B230) -> 2024 | Y230: =C230-B230 -> 4 | Z230: =P230 -> 0.15 | AA230: =N230*O230*(1-P230) -> 2715.2145 | AB230: =Q230-R230 -> 1163.66 | AC230: =IF(OR(B230="",C230="",AA230<=0),"Invalid",IF(Y230<0,"Warning",IF(Z230>100%,"Warning","Clean"))) -> Clean
A231: ORD-2025-10230 | B231: 45836 | C231: 45842 | D231: CUST-1943 | E231: =PROPER(TRIM([1]raw_orders!E231)) -> Rohan Mehta | F231: =PROPER(TRIM([1]raw_orders!F231)) -> Consumer | G231: =IF('[1]Cleaned Text Field'!G231="","Unknown",'[1]Cleaned Text Field'!G231) -> South | H231: =PROPER(TRIM([1]raw_orders!H231)) -> Telangana | I231: =PROPER(TRIM([1]raw_orders!I231)) -> Hyderabad | J231: =PROPER(TRIM([1]raw_orders!J231)) -> Furniture | K231: =PROPER(TRIM([1]raw_orders!K231)) -> Bookcases | L231: Smart Bookcases 662 | M231: =IF('[1]Cleaned Text Field'!M231="","Unknown",'[1]Cleaned Text Field'!M231) -> First Class | N231: =IF('[1]Cleaned Text Field'!N231="",0,'[1]Cleaned Text Field'!N231) -> 3 | O231: 2886.23 | P231: =IF('[1]Cleaned Text Field'!P231="",0,'[1]Cleaned Text Field'!P231) -> 0 | Q231: 8658.69 | R231: 5535.94 | S231: 3122.75 | T231: =PROPER(TRIM([1]raw_orders!T231)) -> Refunded | U231: =PROPER(TRIM([1]raw_orders!U231)) -> Returned | V231: =IF(Q231=0,0,S231/Q231) -> 0.36064924 | W231: =TEXT(B231,"mmmm") -> June | X231: =YEAR(B231) -> 2025 | Y231: =C231-B231 -> 6 | Z231: =P231 -> 0 | AA231: =N231*O231*(1-P231) -> 8658.69 | AB231: =Q231-R231 -> 3122.75 | AC231: =IF(OR(B231="",C231="",AA231<=0),"Invalid",IF(Y231<0,"Warning",IF(Z231>100%,"Warning","Clean"))) -> Clean
A232: ORD-2024-10231 | B232: 45440 | C232: 45357 | D232: CUST-3434 | E232: =PROPER(TRIM([1]raw_orders!E232)) -> Neha Gupta | F232: =PROPER(TRIM([1]raw_orders!F232)) -> Small Business | G232: =IF('[1]Cleaned Text Field'!G232="","Unknown",'[1]Cleaned Text Field'!G232) -> North | H232: =PROPER(TRIM([1]raw_orders!H232)) -> Rajasthan | I232: =PROPER(TRIM([1]raw_orders!I232)) -> Jaipur | J232: =PROPER(TRIM([1]raw_orders!J232)) -> Office Supplies | K232: =PROPER(TRIM([1]raw_orders!K232)) -> Paper | L232: Eco Paper 937 | M232: =IF('[1]Cleaned Text Field'!M232="","Unknown",'[1]Cleaned Text Field'!M232) -> Standard Class | N232: =IF('[1]Cleaned Text Field'!N232="",0,'[1]Cleaned Text Field'!N232) -> 8 | O232: 1540.33 | P232: =IF('[1]Cleaned Text Field'!P232="",0,'[1]Cleaned Text Field'!P232) -> 0.1 | Q232: 11090.38 | R232: 8840.95 | S232: 2249.43 | T232: =PROPER(TRIM([1]raw_orders!T232)) -> Paid | U232: =PROPER(TRIM([1]raw_orders!U232)) -> Completed | V232: =IF(Q232=0,0,S232/Q232) -> 0.20282713 | W232: =TEXT(B232,"mmmm") -> May | X232: =YEAR(B232) -> 2024 | Y232: =C232-B232 -> -83 | Z232: =P232 -> 0.1 | AA232: =N232*O232*(1-P232) -> 11090.376 | AB232: =Q232-R232 -> 2249.43 | AC232: =IF(OR(B232="",C232="",AA232<=0),"Invalid",IF(Y232<0,"Warning",IF(Z232>100%,"Warning","Clean"))) -> Warning
...

Sheet Missing_Value_Summary
A1: Field | B1: Missing Count | C1: Action Taken
A2: order_id | B2: =COUNTIF(A2:A1000,"Unknown") -> 0
A3: order_date | B3: 0
A4: ship_date | B4: 0
A5: customer_id | B5: 0
A6: customer_name | B6: 0
A7: segment | B7: 0
A8: region | B8: =COUNTIF(data!G2:G933,"Unknown") -> 26 | C8: Filled with Unknown
A9: state | B9: 0
A10: city | B10: 0
A11: category | B11: 0
A12: sub_category | B12: 0
A13: product_name | B13: 0
A14: ship_mode | B14: =COUNTIF(data!M2:M933,"Unknown") -> 22 | C14: Filled with Unknown
A15: quantity | B15: 0
A16: unit_price | B16: 0
A17: discount | B17: =COUNTIF(data!P2:P933,0) -> 263 | C17: Filled with 0.00 if valid
A18: sales | B18: 0
A19: cost | B19: 0
A20: profit | B20: 0
A21: payment_status | B21: 0
A22: order_status | B22: 0
A23: Profit Margin | B23: 0
A24: Order moth | B24: 0
A25: Order Year | B25: 0
A26: Shipping_Delay_Days | B26: 0
A27: Cleaned Discount | B27: =COUNTIF(data!Z2:Z933,0%) -> 263 | C27: Filled with 0 if valid
A28: Calculated Sales | B28: 0
A29: Calculated Profit | B29: 0
A30: Data Quality Flag | B30: 0

Sheet Duplicate_Summary
A1: Metric | B1: Value
A2: Exact duplicate rows | B2: 20
A3: Duplicate order IDs | B3: 31
A4: Records removed | B4: 20
A5: Records flagged | B5: 31
A6: Logic | B6: Exact duplicates removed; conflicting IDs flagged.

Sheet Invalid_Discount_Summary
A1: Metric | B1: Count
A2: Missing | B2: =COUNTIF(data!Z2:Z933,0%) -> 263
A3: Negative | B3: =COUNTIF(data!Z2:'data'!Z933,"<0%") -> 16
A4: > Allowed Range | B4: =COUNTIF(data!Z3:'data'!Z934,">0%") -> 652
A5: Total Invalid | B5: 16

Sheet Sales_Profit_Calculation_Mismat
A1: Metric | B1: Count
A2: Sales Mismatch | B2: =COUNTIFS(data!Q2:Q933,data!AA2:AA933) -> 1
A3: Profit Mismatch | B3: =COUNTIFS(data!S2:S933,data!AB2:AB933) -> 1

Sheet Final_Clean_vs_Flagged
A1: Metric | B1: Count
A2: Total | B2: 932
A3: Clean | B3: =COUNTIF(data!AC2:AC933,"Clean") -> 838
A4: Warning | B4: =COUNTIF(data!AC2:AC933,"Warning") -> 94
A5: Invalid | B5: =COUNTIF(data!AC2:AC933,"Invalid") -> 0
